Traceback (most recent call last):
  File "/opt/hostedtoolcache/Python/3.9.5/x64/lib/python3.9/site-packages/jupyter_cache/executors/utils.py", line 51, in single_nb_execution
    executenb(
  File "/opt/hostedtoolcache/Python/3.9.5/x64/lib/python3.9/site-packages/nbclient/client.py", line 1112, in execute
    return NotebookClient(nb=nb, resources=resources, km=km, **kwargs).execute()
  File "/opt/hostedtoolcache/Python/3.9.5/x64/lib/python3.9/site-packages/nbclient/util.py", line 74, in wrapped
    return just_run(coro(*args, **kwargs))
  File "/opt/hostedtoolcache/Python/3.9.5/x64/lib/python3.9/site-packages/nbclient/util.py", line 53, in just_run
    return loop.run_until_complete(coro)
  File "/opt/hostedtoolcache/Python/3.9.5/x64/lib/python3.9/asyncio/base_events.py", line 642, in run_until_complete
    return future.result()
  File "/opt/hostedtoolcache/Python/3.9.5/x64/lib/python3.9/site-packages/nbclient/client.py", line 553, in async_execute
    await self.async_execute_cell(
  File "/opt/hostedtoolcache/Python/3.9.5/x64/lib/python3.9/site-packages/nbclient/client.py", line 857, in async_execute_cell
    self._check_raise_for_error(cell, exec_reply)
  File "/opt/hostedtoolcache/Python/3.9.5/x64/lib/python3.9/site-packages/nbclient/client.py", line 760, in _check_raise_for_error
    raise CellExecutionError.from_cell_and_msg(cell, exec_reply_content)
nbclient.exceptions.CellExecutionError: An error occurred while executing the following cell:
------------------
mk = MeshKernel(is_geographic=False)
------------------

[0;31m---------------------------------------------------------------------------[0m
[0;31mOSError[0m                                   Traceback (most recent call last)
[0;32m<ipython-input-6-baddf649bdfb>[0m in [0;36m<module>[0;34m[0m
[0;32m----> 1[0;31m [0mmk[0m [0;34m=[0m [0mMeshKernel[0m[0;34m([0m[0mis_geographic[0m[0;34m=[0m[0;32mFalse[0m[0;34m)[0m[0;34m[0m[0;34m[0m[0m
[0m
[0;32m~/work/MeshKernelPy/MeshKernelPy/meshkernel/meshkernel.py[0m in [0;36m__init__[0;34m(self, is_geographic)[0m
[1;32m     61[0m             [0;32mraise[0m [0mOSError[0m[0;34m([0m[0;34m"Unsupported operating system"[0m[0;34m)[0m[0;34m[0m[0;34m[0m[0m
[1;32m     62[0m [0;34m[0m[0m
[0;32m---> 63[0;31m         [0mself[0m[0;34m.[0m[0mlib[0m [0;34m=[0m [0mCDLL[0m[0;34m([0m[0mstr[0m[0;34m([0m[0mlib_path[0m[0;34m)[0m[0;34m)[0m[0;34m[0m[0;34m[0m[0m
[0m[1;32m     64[0m         [0mself[0m[0;34m.[0m[0m_allocate_state[0m[0;34m([0m[0mis_geographic[0m[0;34m)[0m[0;34m[0m[0;34m[0m[0m
[1;32m     65[0m [0;34m[0m[0m

[0;32m/opt/hostedtoolcache/Python/3.9.5/x64/lib/python3.9/ctypes/__init__.py[0m in [0;36m__init__[0;34m(self, name, mode, handle, use_errno, use_last_error, winmode)[0m
[1;32m    372[0m [0;34m[0m[0m
[1;32m    373[0m         [0;32mif[0m [0mhandle[0m [0;32mis[0m [0;32mNone[0m[0;34m:[0m[0;34m[0m[0;34m[0m[0m
[0;32m--> 374[0;31m             [0mself[0m[0;34m.[0m[0m_handle[0m [0;34m=[0m [0m_dlopen[0m[0;34m([0m[0mself[0m[0;34m.[0m[0m_name[0m[0;34m,[0m [0mmode[0m[0;34m)[0m[0;34m[0m[0;34m[0m[0m
[0m[1;32m    375[0m         [0;32melse[0m[0;34m:[0m[0;34m[0m[0;34m[0m[0m
[1;32m    376[0m             [0mself[0m[0;34m.[0m[0m_handle[0m [0;34m=[0m [0mhandle[0m[0;34m[0m[0;34m[0m[0m

[0;31mOSError[0m: /home/runner/work/MeshKernelPy/MeshKernelPy/meshkernel/libMeshKernelApi.so: cannot open shared object file: No such file or directory
OSError: /home/runner/work/MeshKernelPy/MeshKernelPy/meshkernel/libMeshKernelApi.so: cannot open shared object file: No such file or directory

